2025-01-04 13:44:05,189 - __main__ - INFO - Program started
2025-01-04 13:44:05,189 - src.data_loader - DEBUG - DataLoader initialized with data_dir: data
2025-01-04 13:44:05,189 - src.openai_client - DEBUG - OpenAIClient initialized with model_name: gpt-4o
2025-01-04 13:44:05,189 - src.processor - DEBUG - Processor initialized
2025-01-04 13:44:05,189 - src.visualizer - DEBUG - Visualizer initialized with output_dir: output
2025-01-04 13:44:05,189 - __main__ - ERROR - An error occurred during exam processing: name 'questions' is not defined
Traceback (most recent call last):
  File "/Users/junghyeon/PycharmProjects/FINOVA_AGENT/main.py", line 54, in process_single_exam
    result = processor.process_exam(exam_name, start_num, end_num)
             ^^^^^^^^^^^^^^^^^^^^^^^^^^^^^^^^^^^^^^^^^^^^^^^^^^^^^
  File "/Users/junghyeon/PycharmProjects/FINOVA_AGENT/src/processor.py", line 29, in process_exam
    if not questions:
           ^^^^^^^^^
NameError: name 'questions' is not defined
2025-01-04 13:44:05,191 - __main__ - INFO - Program completed
